Workbook
Name PriceRange: #REF!
Name SalesRange: #REF!

Sheet Solution
A1: Last Name
A2: First Name
A3: ID
A6: a. create a monthly aggregation of sales data
A7: input product A monthly sales in February 2012 | B7: =+Sales!N19 -> 6693270
A8: input product B montly sales in December 2019 | B8: =+Sales!P113 -> 6892660
A11: b. calculate average monthly price
A12: what was product A average price in February 2012? | B12: =+Sales!Q19 -> 470
A13: what was product B average price in December 2019? | B13: =+Sales!R113 -> 730
A14: which month is the discount month for product A? | B14: =+Sales!U128 -> October
A15: which month is the discount month for product B? | B15: =+Sales!V128 -> June
A18: c. percentage returns by month
A19: input product A percentage returns for sales in February 2012 | B19: =+Sales!X19 -> 0.084825504
A20: input product B percentage returns for sales in December 2019 | B20: =+Sales!Z113 -> 0.064604957
A23: d. percentage warrantry exercised by month
A24: input product A percentage warranty exercises for sales in February 2012 | B24: =+Sales!Y19 -> 0.040657257
A25: input product B percentage warranty exercises for sales in December 2019 | B25: =+Sales!AA113 -> 0.037597967

Sheet Sales
A2: Sales Data
A4: Date | B4: A | D4: B | AC4: GRAPHS
B5: Units Sold | C5: Total Sales | D5: Units Sold | E5: Total Sales | G5: year | H5: month | I5: month | K5: Month | L5: Month | M5: Q_A | N5: R_A | O5: Q_B | P5: R_B | Q5: price_A | R5: price_B | S5: discount_month_A | T5: discount_month_B | U5: work1 | V5: work2 | W5: Month | X5: Return A | Y5: Warranty A | Z5: Return B | AA5: Warranty B | AC5: Month | AD5: Quantity (A) | AE5: Revenue (A) | AF5: Quantity (B) | AG5: Revenue (B)
A6: 40544 | B6: 425 | C6: 199750 | D6: 322 | E6: 235060 | G6: =+YEAR(A6) -> 2011 | H6: =+MONTH(A6) -> 1 | I6: =+H6+(G6-2011)*12 -> 1 | K6: =+'Warranties & Returns'!A6 -> January 2011 | L6: 1 | M6: =+SUMIF($I$6:$I$3658,$L6,B$6:B$3658) -> 14630 | N6: =+SUMIF($I$6:$I$3658,$L6,C$6:C$3658) -> 6876100 | O6: =+SUMIF($I$6:$I$3658,$L6,D$6:D$3658) -> 9164 | P6: =+SUMIF($I$6:$I$3658,$L6,E$6:E$3658) -> 6689720 | Q6: =+N6/M6 -> 470 | R6: =+P6/O6 -> 730 | S6: =+IF(Q6<AVERAGE(Q$6:Q$125),1,0) -> 0 | T6: =+IF(R6<AVERAGE(R$6:R$125),1,0) -> 0 | U6: =+S6*L6 -> 0 | V6: =+T6*L6 -> 0 | W6: =+AC6 -> January 2011 | X6: =+'Warranties & Returns'!B7/Sales!M6 -> 0.079972659 | Y6: =+'Warranties & Returns'!C8/Sales!M6 -> 0.043814081 | Z6: =+'Warranties & Returns'!D7/Sales!O6 -> 0.062745526 | AA6: =+'Warranties & Returns'!E8/Sales!O6 -> 0.048232213 | AC6: =+K6 -> January 2011 | AD6: =+M6 -> 14630 | AE6: =+N6 -> 6876100 | AF6: =+O6 -> 9164 | AG6: =+P6 -> 6689720
A7: 40545 | B7: 434 | C7: 203980 | D7: 329 | E7: 240170 | G7: =+YEAR(A7) -> 2011 | H7: =+MONTH(A7) -> 1 | I7: =+H7+(G7-2011)*12 -> 1 | K7: =+'Warranties & Returns'!A7 -> February 2011 | L7: 2 | M7: =+SUMIF($I$6:$I$3658,$L7,B$6:B$3658) -> 12983 | N7: =+SUMIF($I$6:$I$3658,$L7,C$6:C$3658) -> 6102010 | O7: =+SUMIF($I$6:$I$3658,$L7,D$6:D$3658) -> 8419 | P7: =+SUMIF($I$6:$I$3658,$L7,E$6:E$3658) -> 6145870 | Q7: =+N7/M7 -> 470 | R7: =+P7/O7 -> 730 | S7: =+IF(Q7<AVERAGE(Q$6:Q$125),1,0) -> 0 | T7: =+IF(R7<AVERAGE(R$6:R$125),1,0) -> 0 | U7: =+S7*L7 -> 0 | V7: =+T7*L7 -> 0 | W7: =+AC7 -> February 2011 | X7: =+'Warranties & Returns'!B8/Sales!M7 -> 0.088885466 | Y7: =+'Warranties & Returns'!C9/Sales!M7 -> 0.046445352 | Z7: =+'Warranties & Returns'!D8/Sales!O7 -> 0.061289939 | AA7: =+'Warranties & Returns'!E9/Sales!O7 -> 0.050599834 | AC7: =+K7 -> February 2011 | AD7: =+M7 -> 12983 | AE7: =+N7 -> 6102010 | AF7: =+O7 -> 8419 | AG7: =+P7 -> 6145870
A8: 40546 | B8: 491 | C8: 230770 | D8: 310 | E8: 226300 | G8: =+YEAR(A8) -> 2011 | H8: =+MONTH(A8) -> 1 | I8: =+H8+(G8-2011)*12 -> 1 | K8: =+'Warranties & Returns'!A8 -> March 2011 | L8: 3 | M8: =+SUMIF($I$6:$I$3658,$L8,B$6:B$3658) -> 14515 | N8: =+SUMIF($I$6:$I$3658,$L8,C$6:C$3658) -> 6822050 | O8: =+SUMIF($I$6:$I$3658,$L8,D$6:D$3658) -> 9424 | P8: =+SUMIF($I$6:$I$3658,$L8,E$6:E$3658) -> 6879520 | Q8: =+N8/M8 -> 470 | R8: =+P8/O8 -> 730 | S8: =+IF(Q8<AVERAGE(Q$6:Q$125),1,0) -> 0 | T8: =+IF(R8<AVERAGE(R$6:R$125),1,0) -> 0 | U8: =+S8*L8 -> 0 | V8: =+T8*L8 -> 0 | W8: =+AC8 -> March 2011 | X8: =+'Warranties & Returns'!B9/Sales!M8 -> 0.083844299 | Y8: =+'Warranties & Returns'!C10/Sales!M8 -> 0.034653806 | Z8: =+'Warranties & Returns'!D9/Sales!O8 -> 0.065152801 | AA8: =+'Warranties & Returns'!E10/Sales!O8 -> 0.047219864 | AC8: =+K8 -> March 2011 | AD8: =+M8 -> 14515 | AE8: =+N8 -> 6822050 | AF8: =+O8 -> 9424 | AG8: =+P8 -> 6879520
A9: 40547 | B9: 435 | C9: 204450 | D9: 303 | E9: 221190 | G9: =+YEAR(A9) -> 2011 | H9: =+MONTH(A9) -> 1 | I9: =+H9+(G9-2011)*12 -> 1 | K9: =+'Warranties & Returns'!A9 -> April 2011 | L9: 4 | M9: =+SUMIF($I$6:$I$3658,$L9,B$6:B$3658) -> 14294 | N9: =+SUMIF($I$6:$I$3658,$L9,C$6:C$3658) -> 6718180 | O9: =+SUMIF($I$6:$I$3658,$L9,D$6:D$3658) -> 19599 | P9: =+SUMIF($I$6:$I$3658,$L9,E$6:E$3658) -> 14307270 | Q9: =+N9/M9 -> 470 | R9: =+P9/O9 -> 730 | S9: =+IF(Q9<AVERAGE(Q$6:Q$125),1,0) -> 0 | T9: =+IF(R9<AVERAGE(R$6:R$125),1,0) -> 0 | U9: =+S9*L9 -> 0 | V9: =+T9*L9 -> 0 | W9: =+AC9 -> April 2011 | X9: =+'Warranties & Returns'!B10/Sales!M9 -> 0.089687981 | Y9: =+'Warranties & Returns'!C11/Sales!M9 -> 0.036798657 | Z9: =+'Warranties & Returns'!D10/Sales!O9 -> 0.064697178 | AA9: =+'Warranties & Returns'!E11/Sales!O9 -> 0.048880045 | AC9: =+K9 -> April 2011 | AD9: =+M9 -> 14294 | AE9: =+N9 -> 6718180 | AF9: =+O9 -> 19599 | AG9: =+P9 -> 14307270
A10: 40548 | B10: 519 | C10: 243930 | D10: 238 | E10: 173740 | G10: =+YEAR(A10) -> 2011 | H10: =+MONTH(A10) -> 1 | I10: =+H10+(G10-2011)*12 -> 1 | K10: =+'Warranties & Returns'!A10 -> May 2011 | L10: 5 | M10: =+SUMIF($I$6:$I$3658,$L10,B$6:B$3658) -> 13916 | N10: =+SUMIF($I$6:$I$3658,$L10,C$6:C$3658) -> 6540520 | O10: =+SUMIF($I$6:$I$3658,$L10,D$6:D$3658) -> 20733 | P10: =+SUMIF($I$6:$I$3658,$L10,E$6:E$3658) -> 15135090 | Q10: =+N10/M10 -> 470 | R10: =+P10/O10 -> 730 | S10: =+IF(Q10<AVERAGE(Q$6:Q$125),1,0) -> 0 | T10: =+IF(R10<AVERAGE(R$6:R$125),1,0) -> 0 | U10: =+S10*L10 -> 0 | V10: =+T10*L10 -> 0 | W10: =+AC10 -> May 2011 | X10: =+'Warranties & Returns'!B11/Sales!M10 -> 0.084291463 | Y10: =+'Warranties & Returns'!C12/Sales!M10 -> 0.04512791 | Z10: =+'Warranties & Returns'!D11/Sales!O10 -> 0.062364347 | AA10: =+'Warranties & Returns'!E12/Sales!O10 -> 0.048473448 | AC10: =+K10 -> May 2011 | AD10: =+M10 -> 13916 | AE10: =+N10 -> 6540520 | AF10: =+O10 -> 20733 | AG10: =+P10 -> 15135090
A11: 40549 | B11: 433 | C11: 203510 | D11: 313 | E11: 228490 | G11: =+YEAR(A11) -> 2011 | H11: =+MONTH(A11) -> 1 | I11: =+H11+(G11-2011)*12 -> 1 | K11: =+'Warranties & Returns'!A11 -> June 2011 | L11: 6 | M11: =+SUMIF($I$6:$I$3658,$L11,B$6:B$3658) -> 13891 | N11: =+SUMIF($I$6:$I$3658,$L11,C$6:C$3658) -> 6528770 | O11: =+SUMIF($I$6:$I$3658,$L11,D$6:D$3658) -> 21435 | P11: =+SUMIF($I$6:$I$3658,$L11,E$6:E$3658) -> 6259020 | Q11: =+N11/M11 -> 470 | R11: =+P11/O11 -> 292 | S11: =+IF(Q11<AVERAGE(Q$6:Q$125),1,0) -> 0 | T11: =+IF(R11<AVERAGE(R$6:R$125),1,0) -> 1 | U11: =+S11*L11 -> 0 | V11: =+T11*L11 -> 6 | W11: =+AC11 -> June 2011 | X11: =+'Warranties & Returns'!B12/Sales!M11 -> 0.083579296 | Y11: =+'Warranties & Returns'!C13/Sales!M11 -> 0.037722266 | Z11: =+'Warranties & Returns'!D12/Sales!O11 -> 0 | AA11: =+'Warranties & Returns'!E13/Sales!O11 -> 0.053044087 | AC11: =+K11 -> June 2011 | AD11: =+M11 -> 13891 | AE11: =+N11 -> 6528770 | AF11: =+O11 -> 21435 | AG11: =+P11 -> 6259020
A12: 40550 | B12: 507 | C12: 238290 | D12: 286 | E12: 208780 | G12: =+YEAR(A12) -> 2011 | H12: =+MONTH(A12) -> 1 | I12: =+H12+(G12-2011)*12 -> 1 | K12: =+'Warranties & Returns'!A12 -> July 2011 | L12: 7 | M12: =+SUMIF($I$6:$I$3658,$L12,B$6:B$3658) -> 14260 | N12: =+SUMIF($I$6:$I$3658,$L12,C$6:C$3658) -> 6702200 | O12: =+SUMIF($I$6:$I$3658,$L12,D$6:D$3658) -> 9121 | P12: =+SUMIF($I$6:$I$3658,$L12,E$6:E$3658) -> 6658330 | Q12: =+N12/M12 -> 470 | R12: =+P12/O12 -> 730 | S12: =+IF(Q12<AVERAGE(Q$6:Q$125),1,0) -> 0 | T12: =+IF(R12<AVERAGE(R$6:R$125),1,0) -> 0 | U12: =+S12*L12 -> 0 | V12: =+T12*L12 -> 0 | W12: =+AC12 -> July 2011 | X12: =+'Warranties & Returns'!B13/Sales!M12 -> 0.078821879 | Y12: =+'Warranties & Returns'!C14/Sales!M12 -> 0.045932679 | Z12: =+'Warranties & Returns'!D13/Sales!O12 -> 0.068194277 | AA12: =+'Warranties & Returns'!E14/Sales!O12 -> 0.048898147 | AC12: =+K12 -> July 2011 | AD12: =+M12 -> 14260 | AE12: =+N12 -> 6702200 | AF12: =+O12 -> 9121 | AG12: =+P12 -> 6658330
A13: 40551 | B13: 491 | C13: 230770 | D13: 303 | E13: 221190 | G13: =+YEAR(A13) -> 2011 | H13: =+MONTH(A13) -> 1 | I13: =+H13+(G13-2011)*12 -> 1 | K13: =+'Warranties & Returns'!A13 -> August 2011 | L13: 8 | M13: =+SUMIF($I$6:$I$3658,$L13,B$6:B$3658) -> 21795 | N13: =+SUMIF($I$6:$I$3658,$L13,C$6:C$3658) -> 10243650 | O13: =+SUMIF($I$6:$I$3658,$L13,D$6:D$3658) -> 9342 | P13: =+SUMIF($I$6:$I$3658,$L13,E$6:E$3658) -> 6819660 | Q13: =+N13/M13 -> 470 | R13: =+P13/O13 -> 730 | S13: =+IF(Q13<AVERAGE(Q$6:Q$125),1,0) -> 0 | T13: =+IF(R13<AVERAGE(R$6:R$125),1,0) -> 0 | U13: =+S13*L13 -> 0 | V13: =+T13*L13 -> 0 | W13: =+AC13 -> August 2011 | X13: =+'Warranties & Returns'!B14/Sales!M13 -> 0.093324157 | Y13: =+'Warranties & Returns'!C15/Sales!M13 -> 0.045606791 | Z13: =+'Warranties & Returns'!D14/Sales!O13 -> 0.065617641 | AA13: =+'Warranties & Returns'!E15/Sales!O13 -> 0.0482766 | AC13: =+K13 -> August 2011 | AD13: =+M13 -> 21795 | AE13: =+N13 -> 10243650 | AF13: =+O13 -> 9342 | AG13: =+P13 -> 6819660
A14: 40552 | B14: 468 | C14: 219960 | D14: 321 | E14: 234330 | G14: =+YEAR(A14) -> 2011 | H14: =+MONTH(A14) -> 1 | I14: =+H14+(G14-2011)*12 -> 1 | K14: =+'Warranties & Returns'!A14 -> September 2011 | L14: 9 | M14: =+SUMIF($I$6:$I$3658,$L14,B$6:B$3658) -> 21360 | N14: =+SUMIF($I$6:$I$3658,$L14,C$6:C$3658) -> 10039200 | O14: =+SUMIF($I$6:$I$3658,$L14,D$6:D$3658) -> 8776 | P14: =+SUMIF($I$6:$I$3658,$L14,E$6:E$3658) -> 6406480 | Q14: =+N14/M14 -> 470 | R14: =+P14/O14 -> 730 | S14: =+IF(Q14<AVERAGE(Q$6:Q$125),1,0) -> 0 | T14: =+IF(R14<AVERAGE(R$6:R$125),1,0) -> 0 | U14: =+S14*L14 -> 0 | V14: =+T14*L14 -> 0 | W14: =+AC14 -> September 2011 | X14: =+'Warranties & Returns'!B15/Sales!M14 -> 0.082490637 | Y14: =+'Warranties & Returns'!C16/Sales!M14 -> 0.041900749 | Z14: =+'Warranties & Returns'!D15/Sales!O14 -> 0.066545123 | AA14: =+'Warranties & Returns'!E16/Sales!O14 -> 0.044895169 | AC14: =+K14 -> September 2011 | AD14: =+M14 -> 21360 | AE14: =+N14 -> 10039200 | AF14: =+O14 -> 8776 | AG14: =+P14 -> 6406480
A15: 40553 | B15: 518 | C15: 243460 | D15: 307 | E15: 224110 | G15: =+YEAR(A15) -> 2011 | H15: =+MONTH(A15) -> 1 | I15: =+H15+(G15-2011)*12 -> 1 | K15: =+'Warranties & Returns'!A15 -> October 2011 | L15: 10 | M15: =+SUMIF($I$6:$I$3658,$L15,B$6:B$3658) -> 17801 | N15: =+SUMIF($I$6:$I$3658,$L15,C$6:C$3658) -> 5229043.8 | O15: =+SUMIF($I$6:$I$3658,$L15,D$6:D$3658) -> 9417 | P15: =+SUMIF($I$6:$I$3658,$L15,E$6:E$3658) -> 6874410 | Q15: =+N15/M15 -> 293.75 | R15: =+P15/O15 -> 730 | S15: =+IF(Q15<AVERAGE(Q$6:Q$125),1,0) -> 1 | T15: =+IF(R15<AVERAGE(R$6:R$125),1,0) -> 0 | U15: =+S15*L15 -> 10 | V15: =+T15*L15 -> 0 | W15: =+AC15 -> October 2011 | X15: =+'Warranties & Returns'!B16/Sales!M15 -> 0 | Y15: =+'Warranties & Returns'!C17/Sales!M15 -> 0.027863603 | Z15: =+'Warranties & Returns'!D16/Sales!O15 -> 0.064139323 | AA15: =+'Warranties & Returns'!E17/Sales!O15 -> 0.050228311 | AC15: =+K15 -> October 2011 | AD15: =+M15 -> 17801 | AE15: =+N15 -> 5229043.8 | AF15: =+O15 -> 9417 | AG15: =+P15 -> 6874410
A16: 40554 | B16: 497 | C16: 233590 | D16: 281 | E16: 205130 | G16: =+YEAR(A16) -> 2011 | H16: =+MONTH(A16) -> 1 | I16: =+H16+(G16-2011)*12 -> 1 | K16: =+'Warranties & Returns'!A16 -> November 2011 | L16: 11 | M16: =+SUMIF($I$6:$I$3658,$L16,B$6:B$3658) -> 14091 | N16: =+SUMIF($I$6:$I$3658,$L16,C$6:C$3658) -> 6622770 | O16: =+SUMIF($I$6:$I$3658,$L16,D$6:D$3658) -> 9120 | P16: =+SUMIF($I$6:$I$3658,$L16,E$6:E$3658) -> 6657600 | Q16: =+N16/M16 -> 470 | R16: =+P16/O16 -> 730 | S16: =+IF(Q16<AVERAGE(Q$6:Q$125),1,0) -> 0 | T16: =+IF(R16<AVERAGE(R$6:R$125),1,0) -> 0 | U16: =+S16*L16 -> 0 | V16: =+T16*L16 -> 0 | W16: =+AC16 -> November 2011 | X16: =+'Warranties & Returns'!B17/Sales!M16 -> 0.083031722 | Y16: =+'Warranties & Returns'!C18/Sales!M16 -> 0.033496558 | Z16: =+'Warranties & Returns'!D17/Sales!O16 -> 0.055701754 | AA16: =+'Warranties & Returns'!E18/Sales!O16 -> 0.051096491 | AC16: =+K16 -> November 2011 | AD16: =+M16 -> 14091 | AE16: =+N16 -> 6622770 | AF16: =+O16 -> 9120 | AG16: =+P16 -> 6657600
A17: 40555 | B17: 443 | C17: 208210 | D17: 297 | E17: 216810 | G17: =+YEAR(A17) -> 2011 | H17: =+MONTH(A17) -> 1 | I17: =+H17+(G17-2011)*12 -> 1 | K17: =+'Warranties & Returns'!A17 -> December 2011 | L17: 12 | M17: =+SUMIF($I$6:$I$3658,$L17,B$6:B$3658) -> 14222 | N17: =+SUMIF($I$6:$I$3658,$L17,C$6:C$3658) -> 6684340 | O17: =+SUMIF($I$6:$I$3658,$L17,D$6:D$3658) -> 9613 | P17: =+SUMIF($I$6:$I$3658,$L17,E$6:E$3658) -> 7017490 | Q17: =+N17/M17 -> 470 | R17: =+P17/O17 -> 730 | S17: =+IF(Q17<AVERAGE(Q$6:Q$125),1,0) -> 0 | T17: =+IF(R17<AVERAGE(R$6:R$125),1,0) -> 0 | U17: =+S17*L17 -> 0 | V17: =+T17*L17 -> 0 | W17: =+AC17 -> December 2011 | X17: =+'Warranties & Returns'!B18/Sales!M17 -> 0.085993531 | Y17: =+'Warranties & Returns'!C19/Sales!M17 -> 0.040711574 | Z17: =+'Warranties & Returns'!D18/Sales!O17 -> 0.062831582 | AA17: =+'Warranties & Returns'!E19/Sales!O17 -> 0.065016124 | AC17: =+K17 -> December 2011 | AD17: =+M17 -> 14222 | AE17: =+N17 -> 6684340 | AF17: =+O17 -> 9613 | AG17: =+P17 -> 7017490
... A125: 40663 | B125: 543 | C125: 255210 | D125: 693 | E125: 505890 | G125: =+YEAR(A125) -> 2011 | H125: =+MONTH(A125) -> 4 | I125: =+H125+(G125-2011)*12 -> 4 | K125: =+'Warranties & Returns'!A125 -> December 2020 | L125: 120 | M125: =+SUMIF($I$6:$I$3658,$L125,B$6:B$3658) -> 14544 | N125: =+SUMIF($I$6:$I$3658,$L125,C$6:C$3658) -> 6835680 | O125: =+SUMIF($I$6:$I$3658,$L125,D$6:D$3658) -> 9351 | P125: =+SUMIF($I$6:$I$3658,$L125,E$6:E$3658) -> 6826230 | Q125: =+N125/M125 -> 470 | R125: =+P125/O125 -> 730 | S125: =+IF(Q125<AVERAGE(Q$6:Q$125),1,0) -> 0 | T125: =+IF(R125<AVERAGE(R$6:R$125),1,0) -> 0 | U125: =+S125*L125 -> 0 | V125: =+T125*L125 -> 0 | W125: =+AC125 -> December 2020 | X125: =+'Warranties & Returns'!B126/Sales!M125 -> 0 | Y125: =+'Warranties & Returns'!C127/Sales!M125 -> 0 | Z125: =+'Warranties & Returns'!D126/Sales!O125 -> 0 | AA125: =+'Warranties & Returns'!E127/Sales!O125 -> 0 | AC125: =+K125 -> December 2020 | AD125: =+M125 -> 14544 | AE125: =+N125 -> 6835680 | AF125: =+O125 -> 9351 | AG125: =+P125 -> 6826230
A126: 40664 | B126: 450 | C126: 211500 | D126: 721 | E126: 526330 | G126: =+YEAR(A126) -> 2011 | H126: =+MONTH(A126) -> 5 | I126: =+H126+(G126-2011)*12 -> 5
A127: 40665 | B127: 519 | C127: 243930 | D127: 643 | E127: 469390 | G127: =+YEAR(A127) -> 2011 | H127: =+MONTH(A127) -> 5 | I127: =+H127+(G127-2011)*12 -> 5 | U127: =+(SUM(U6:U125)-540)/10 -> 10 | V127: =+(SUM(V6:V125)-540)/10 -> 6
A128: 40666 | B128: 339 | C128: 159330 | D128: 739 | E128: 539470 | G128: =+YEAR(A128) -> 2011 | H128: =+MONTH(A128) -> 5 | I128: =+H128+(G128-2011)*12 -> 5 | U128: =+VLOOKUP(U127,$U$130:$V$141,2) -> October | V128: =+VLOOKUP(V127,$U$130:$V$141,2) -> June
A129: 40667 | B129: 494 | C129: 232180 | D129: 730 | E129: 532900 | G129: =+YEAR(A129) -> 2011 | H129: =+MONTH(A129) -> 5 | I129: =+H129+(G129-2011)*12 -> 5
A130: 40668 | B130: 506 | C130: 237820 | D130: 606 | E130: 442380 | G130: =+YEAR(A130) -> 2011 | H130: =+MONTH(A130) -> 5 | I130: =+H130+(G130-2011)*12 -> 5 | U130: 1 | V130: January
A131: 40669 | B131: 430 | C131: 202100 | D131: 731 | E131: 533630 | G131: =+YEAR(A131) -> 2011 | H131: =+MONTH(A131) -> 5 | I131: =+H131+(G131-2011)*12 -> 5 | U131: 2 | V131: February
A132: 40670 | B132: 426 | C132: 200220 | D132: 718 | E132: 524140 | G132: =+YEAR(A132) -> 2011 | H132: =+MONTH(A132) -> 5 | I132: =+H132+(G132-2011)*12 -> 5 | U132: 3 | V132: March
A133: 40671 | B133: 526 | C133: 247220 | D133: 686 | E133: 500780 | G133: =+YEAR(A133) -> 2011 | H133: =+MONTH(A133) -> 5 | I133: =+H133+(G133-2011)*12 -> 5 | U133: 4 | V133: April
A134: 40672 | B134: 469 | C134: 220430 | D134: 642 | E134: 468660 | G134: =+YEAR(A134) -> 2011 | H134: =+MONTH(A134) -> 5 | I134: =+H134+(G134-2011)*12 -> 5 | U134: 5 | V134: May
A135: 40673 | B135: 439 | C135: 206330 | D135: 682 | E135: 497860 | G135: =+YEAR(A135) -> 2011 | H135: =+MONTH(A135) -> 5 | I135: =+H135+(G135-2011)*12 -> 5 | U135: 6 | V135: June
A136: 40674 | B136: 484 | C136: 227480 | D136: 630 | E136: 459900 | G136: =+YEAR(A136) -> 2011 | H136: =+MONTH(A136) -> 5 | I136: =+H136+(G136-2011)*12 -> 5 | U136: 7 | V136: July
A137: 40675 | B137: 413 | C137: 194110 | D137: 753 | E137: 549690 | G137: =+YEAR(A137) -> 2011 | H137: =+MONTH(A137) -> 5 | I137: =+H137+(G137-2011)*12 -> 5 | U137: 8 | V137: August
A138: 40676 | B138: 512 | C138: 240640 | D138: 668 | E138: 487640 | G138: =+YEAR(A138) -> 2011 | H138: =+MONTH(A138) -> 5 | I138: =+H138+(G138-2011)*12 -> 5 | U138: 9 | V138: September
A139: 40677 | B139: 376 | C139: 176720 | D139: 616 | E139: 449680 | G139: =+YEAR(A139) -> 2011 | H139: =+MONTH(A139) -> 5 | I139: =+H139+(G139-2011)*12 -> 5 | U139: 10 | V139: October
A140: 40678 | B140: 439 | C140: 206330 | D140: 580 | E140: 423400 | G140: =+YEAR(A140) -> 2011 | H140: =+MONTH(A140) -> 5 | I140: =+H140+(G140-2011)*12 -> 5 | U140: 11 | V140: November
A141: 40679 | B141: 403 | C141: 189410 | D141: 670 | E141: 489100 | G141: =+YEAR(A141) -> 2011 | H141: =+MONTH(A141) -> 5 | I141: =+H141+(G141-2011)*12 -> 5 | U141: 12 | V141: December
A142: 40680 | B142: 499 | C142: 234530 | D142: 754 | E142: 550420 | G142: =+YEAR(A142) -> 2011 | H142: =+MONTH(A142) -> 5 | I142: =+H142+(G142-2011)*12 -> 5
A143: 40681 | B143: 438 | C143: 205860 | D143: 622 | E143: 454060 | G143: =+YEAR(A143) -> 2011 | H143: =+MONTH(A143) -> 5 | I143: =+H143+(G143-2011)*12 -> 5
A144: 40682 | B144: 467 | C144: 219490 | D144: 702 | E144: 512460 | G144: =+YEAR(A144) -> 2011 | H144: =+MONTH(A144) -> 5 | I144: =+H144+(G144-2011)*12 -> 5
A145: 40683 | B145: 496 | C145: 233120 | D145: 570 | E145: 416100 | G145: =+YEAR(A145) -> 2011 | H145: =+MONTH(A145) -> 5 | I145: =+H145+(G145-2011)*12 -> 5
A146: 40684 | B146: 483 | C146: 227010 | D146: 682 | E146: 497860 | G146: =+YEAR(A146) -> 2011 | H146: =+MONTH(A146) -> 5 | I146: =+H146+(G146-2011)*12 -> 5
A147: 40685 | B147: 413 | C147: 194110 | D147: 578 | E147: 421940 | G147: =+YEAR(A147) -> 2011 | H147: =+MONTH(A147) -> 5 | I147: =+H147+(G147-2011)*12 -> 5
A148: 40686 | B148: 413 | C148: 194110 | D148: 677 | E148: 494210 | G148: =+YEAR(A148) -> 2011 | H148: =+MONTH(A148) -> 5 | I148: =+H148+(G148-2011)*12 -> 5
A149: 40687 | B149: 453 | C149: 212910 | D149: 649 | E149: 473770 | G149: =+YEAR(A149) -> 2011 | H149: =+MONTH(A149) -> 5 | I149: =+H149+(G149-2011)*12 -> 5
...

Sheet Warranties & Returns
A2: Return & Warranty Claims
A4: Product | B4: A | D4: B
A5: Type | B5: Return | C5: Warranty | D5: Return | E5: Warranty
A6: January 2011
A7: February 2011 | B7: 1170 | D7: 575
A8: March 2011 | B8: 1154 | C8: 641 | D8: 516 | E8: 442
A9: April 2011 | B9: 1217 | C9: 603 | D9: 614 | E9: 426
A10: May 2011 | B10: 1282 | C10: 503 | D10: 1268 | E10: 445
A11: June 2011 | B11: 1173 | C11: 526 | D11: 1293 | E11: 958
A12: July 2011 | B12: 1161 | C12: 628 | D12: 0 | E12: 1005
A13: August 2011 | B13: 1124 | C13: 524 | D13: 622 | E13: 1137
A14: September 2011 | B14: 2034 | C14: 655 | D14: 613 | E14: 446
A15: October 2011 | B15: 1762 | C15: 994 | D15: 584 | E15: 451
A16: November 2011 | B16: 0 | C16: 895 | D16: 604 | E16: 394
A17: December 2011 | B17: 1170 | C17: 496 | D17: 508 | E17: 473
A18: January 2012 | B18: 1223 | C18: 472 | D18: 604 | E18: 466
A19: February 2012 | B19: 1119 | C19: 579 | D19: 650 | E19: 625
... A125: December 2020 | B125: 1132 | C125: 783 | D125: 558 | E125: 489
